Traceback (most recent call last):
  File "C:\Users\USUARIO\anaconda3\lib\site-packages\jupyter_cache\executors\utils.py", line 51, in single_nb_execution
    executenb(
  File "C:\Users\USUARIO\AppData\Roaming\Python\Python39\site-packages\nbclient\client.py", line 1117, in execute
    return NotebookClient(nb=nb, resources=resources, km=km, **kwargs).execute()
  File "C:\Users\USUARIO\AppData\Roaming\Python\Python39\site-packages\nbclient\util.py", line 78, in wrapped
    return just_run(coro(*args, **kwargs))
  File "C:\Users\USUARIO\AppData\Roaming\Python\Python39\site-packages\nbclient\util.py", line 57, in just_run
    return loop.run_until_complete(coro)
  File "C:\Users\USUARIO\anaconda3\lib\asyncio\base_events.py", line 647, in run_until_complete
    return future.result()
  File "C:\Users\USUARIO\AppData\Roaming\Python\Python39\site-packages\nbclient\client.py", line 558, in async_execute
    await self.async_execute_cell(
  File "C:\Users\USUARIO\AppData\Roaming\Python\Python39\site-packages\nbclient\client.py", line 862, in async_execute_cell
    self._check_raise_for_error(cell, exec_reply)
  File "C:\Users\USUARIO\AppData\Roaming\Python\Python39\site-packages\nbclient\client.py", line 765, in _check_raise_for_error
    raise CellExecutionError.from_cell_and_msg(cell, exec_reply_content)
nbclient.exceptions.CellExecutionError: An error occurred while executing the following cell:
------------------
# guardar el dataset en carpeta data set del proyecto en google drive
from google.colab import drive
drive.mount('drive')
df.to_csv('input.csv')
!cp input.csv "/content/drive/MyDrive/ds/proyecto/dataset/"
------------------

[1;31m---------------------------------------------------------------------------[0m
[1;31mModuleNotFoundError[0m                       Traceback (most recent call last)
[1;32m~\AppData\Local\Temp/ipykernel_12692/2302507957.py[0m in [0;36m<module>[1;34m[0m
[0;32m      1[0m [1;31m# guardar el dataset en carpeta data set del proyecto en google drive[0m[1;33m[0m[1;33m[0m[0m
[1;32m----> 2[1;33m [1;32mfrom[0m [0mgoogle[0m[1;33m.[0m[0mcolab[0m [1;32mimport[0m [0mdrive[0m[1;33m[0m[1;33m[0m[0m
[0m[0;32m      3[0m [0mdrive[0m[1;33m.[0m[0mmount[0m[1;33m([0m[1;34m'drive'[0m[1;33m)[0m[1;33m[0m[1;33m[0m[0m
[0;32m      4[0m [0mdf[0m[1;33m.[0m[0mto_csv[0m[1;33m([0m[1;34m'input.csv'[0m[1;33m)[0m[1;33m[0m[1;33m[0m[0m
[0;32m      5[0m [0mget_ipython[0m[1;33m([0m[1;33m)[0m[1;33m.[0m[0msystem[0m[1;33m([0m[1;34m'cp input.csv "/content/drive/MyDrive/ds/proyecto/dataset/"'[0m[1;33m)[0m[1;33m[0m[1;33m[0m[0m

[1;31mModuleNotFoundError[0m: No module named 'google.colab'
ModuleNotFoundError: No module named 'google.colab'

