Traceback (most recent call last):
  File "C:\Users\USUARIO\AppData\Local\Programs\Python\Python310\lib\site-packages\jupyter_cache\executors\utils.py", line 51, in single_nb_execution
    executenb(
  File "C:\Users\USUARIO\AppData\Local\Programs\Python\Python310\lib\site-packages\nbclient\client.py", line 1204, in execute
    return NotebookClient(nb=nb, resources=resources, km=km, **kwargs).execute()
  File "C:\Users\USUARIO\AppData\Local\Programs\Python\Python310\lib\site-packages\nbclient\util.py", line 84, in wrapped
    return just_run(coro(*args, **kwargs))
  File "C:\Users\USUARIO\AppData\Local\Programs\Python\Python310\lib\site-packages\nbclient\util.py", line 62, in just_run
    return loop.run_until_complete(coro)
  File "C:\Users\USUARIO\AppData\Local\Programs\Python\Python310\lib\asyncio\base_events.py", line 646, in run_until_complete
    return future.result()
  File "C:\Users\USUARIO\AppData\Local\Programs\Python\Python310\lib\site-packages\nbclient\client.py", line 663, in async_execute
    await self.async_execute_cell(
  File "C:\Users\USUARIO\AppData\Local\Programs\Python\Python310\lib\site-packages\nbclient\client.py", line 965, in async_execute_cell
    await self._check_raise_for_error(cell, cell_index, exec_reply)
  File "C:\Users\USUARIO\AppData\Local\Programs\Python\Python310\lib\site-packages\nbclient\client.py", line 862, in _check_raise_for_error
    raise CellExecutionError.from_cell_and_msg(cell, exec_reply_content)
nbclient.exceptions.CellExecutionError: An error occurred while executing the following cell:
------------------
import plotly.express as px

# grafico 3dimenseiones 
fig = px.scatter_3d(train, x='high_btc', y='y_lag1', z='Shock-COVID', size='y_lag1',
              color='y_lag1', opacity=0.8)

fig.update_layout(margin=dict(l=0, r=0, b=0, t=0),
                  title={
        'text': "Grafico 3D de impacto COVID",
        'y':0.9,
        'x':0.05
         })
fig.show()
------------------

[1;31m---------------------------------------------------------------------------[0m
[1;31mModuleNotFoundError[0m                       Traceback (most recent call last)
Input [1;32mIn [9][0m, in [0;36m<cell line: 1>[1;34m()[0m
[1;32m----> 1[0m [38;5;28;01mimport[39;00m [38;5;21;01mplotly[39;00m[38;5;21;01m.[39;00m[38;5;21;01mexpress[39;00m [38;5;28;01mas[39;00m [38;5;21;01mpx[39;00m
[0;32m      3[0m [38;5;66;03m# grafico 3dimenseiones [39;00m
[0;32m      4[0m fig [38;5;241m=[39m px[38;5;241m.[39mscatter_3d(train, x[38;5;241m=[39m[38;5;124m'[39m[38;5;124mhigh_btc[39m[38;5;124m'[39m, y[38;5;241m=[39m[38;5;124m'[39m[38;5;124my_lag1[39m[38;5;124m'[39m, z[38;5;241m=[39m[38;5;124m'[39m[38;5;124mShock-COVID[39m[38;5;124m'[39m, size[38;5;241m=[39m[38;5;124m'[39m[38;5;124my_lag1[39m[38;5;124m'[39m,
[0;32m      5[0m               color[38;5;241m=[39m[38;5;124m'[39m[38;5;124my_lag1[39m[38;5;124m'[39m, opacity[38;5;241m=[39m[38;5;241m0.8[39m)

[1;31mModuleNotFoundError[0m: No module named 'plotly'
ModuleNotFoundError: No module named 'plotly'

