Traceback (most recent call last):
  File "/Users/antonellabulla/opt/miniconda3/lib/python3.9/site-packages/jupyter_cache/executors/utils.py", line 51, in single_nb_execution
    executenb(
  File "/Users/antonellabulla/opt/miniconda3/lib/python3.9/site-packages/nbclient/client.py", line 1204, in execute
    return NotebookClient(nb=nb, resources=resources, km=km, **kwargs).execute()
  File "/Users/antonellabulla/opt/miniconda3/lib/python3.9/site-packages/nbclient/util.py", line 84, in wrapped
    return just_run(coro(*args, **kwargs))
  File "/Users/antonellabulla/opt/miniconda3/lib/python3.9/site-packages/nbclient/util.py", line 62, in just_run
    return loop.run_until_complete(coro)
  File "/Users/antonellabulla/opt/miniconda3/lib/python3.9/asyncio/base_events.py", line 642, in run_until_complete
    return future.result()
  File "/Users/antonellabulla/opt/miniconda3/lib/python3.9/site-packages/nbclient/client.py", line 663, in async_execute
    await self.async_execute_cell(
  File "/Users/antonellabulla/opt/miniconda3/lib/python3.9/site-packages/nbclient/client.py", line 965, in async_execute_cell
    await self._check_raise_for_error(cell, cell_index, exec_reply)
  File "/Users/antonellabulla/opt/miniconda3/lib/python3.9/site-packages/nbclient/client.py", line 862, in _check_raise_for_error
    raise CellExecutionError.from_cell_and_msg(cell, exec_reply_content)
nbclient.exceptions.CellExecutionError: An error occurred while executing the following cell:
------------------
# generales
import pandas as pd 
import numpy as np # numpy y pandas to data wrangling 
from datetime import datetime, timedelta # to work w date
import statsmodels.api as sm
import math
from random import sample
from random import choices
import multiprocessing

# visualizaci√≥n
import matplotlib as mpl
import matplotlib.pyplot as plt

# m√©trica
from sklearn.metrics import mean_squared_error

# preprocesamiento
from sklearn.preprocessing import StandardScaler
from sklearn.datasets import load_boston
from sklearn.ensemble import RandomForestRegressor

# modelos
import xgboost as xgb
from sklearn.decomposition import PCA
import statsmodels.api as sm
from sklearn.model_selection import cross_val_score
from sklearn.model_selection import train_test_split
from sklearn.model_selection import RepeatedKFold
from sklearn.model_selection import GridSearchCV
from sklearn.model_selection import ParameterGrid
from sklearn.inspection import permutation_importance
------------------

[0;31m---------------------------------------------------------------------------[0m
[0;31mModuleNotFoundError[0m                       Traceback (most recent call last)
Input [0;32mIn [1][0m, in [0;36m<cell line: 5>[0;34m()[0m
[1;32m      3[0m [38;5;28;01mimport[39;00m [38;5;21;01mnumpy[39;00m [38;5;28;01mas[39;00m [38;5;21;01mnp[39;00m [38;5;66;03m# numpy y pandas to data wrangling [39;00m
[1;32m      4[0m [38;5;28;01mfrom[39;00m [38;5;21;01mdatetime[39;00m [38;5;28;01mimport[39;00m datetime, timedelta [38;5;66;03m# to work w date[39;00m
[0;32m----> 5[0m [38;5;28;01mimport[39;00m [38;5;21;01mstatsmodels[39;00m[38;5;21;01m.[39;00m[38;5;21;01mapi[39;00m [38;5;28;01mas[39;00m [38;5;21;01msm[39;00m
[1;32m      6[0m [38;5;28;01mimport[39;00m [38;5;21;01mmath[39;00m
[1;32m      7[0m [38;5;28;01mfrom[39;00m [38;5;21;01mrandom[39;00m [38;5;28;01mimport[39;00m sample

[0;31mModuleNotFoundError[0m: No module named 'statsmodels'
ModuleNotFoundError: No module named 'statsmodels'

